Workbook
Name Beta: #REF!
Name CostofDebt: #REF!
Name DebtValue: #REF!
Name EquityValue: #REF!
Name MarketReturns: #REF!
Name RiskFreeRate: #REF!
Name TaxRate: #REF!

Sheet One Page Profile
B2: Apple Inc. - One Page Profile
B10: Key Financial Metrics | F10: =F20 -> 2020 | G10: =G20 -> 2021 | H10: =H20 -> 2022 | I10: =I20 -> 2023 | K10: Share Price - 5Y
B11: ='Ratio Analysis'!B9 -> Sales Growth | F11: ='Ratio Analysis'!I9 -> 0.055120804 | G11: ='Ratio Analysis'!J9 -> 0.33259385 | H11: ='Ratio Analysis'!K9 -> 0.077937876 | I11: ='Ratio Analysis'!L9 -> -0.028004605
B12: ='Ratio Analysis'!B16 -> EBITDA Margin | F12: ='Ratio Analysis'!I16 -> 0.28174781 | G12: ='Ratio Analysis'!J16 -> 0.3286698 | H12: ='Ratio Analysis'!K16 -> 0.33104674 | I12: ='Ratio Analysis'!L16 -> 0.32826748
B13: ='Ratio Analysis'!B17 -> EBIT Margin | F13: ='Ratio Analysis'!I17 -> 0.24147314 | G13: ='Ratio Analysis'!J17 -> 0.29782378 | H13: ='Ratio Analysis'!K17 -> 0.30288744 | I13: ='Ratio Analysis'!L17 -> 0.29821412
B14: Gross Profit Margin | F14: ='Historical & Forecasted FS'!I15 -> 0.38233248 | G14: ='Historical & Forecasted FS'!J15 -> 0.4177936 | H14: ='Historical & Forecasted FS'!K15 -> 0.43309631 | I14: ='Historical & Forecasted FS'!L15 -> 0.4413113
B15: ='Ratio Analysis'!B19 -> Net Profit Margin | F15: ='Ratio Analysis'!I19 -> 0.20913611 | G15: ='Ratio Analysis'!J19 -> 0.25881793 | H15: ='Ratio Analysis'!K19 -> 0.25309641 | I15: ='Ratio Analysis'!L19 -> 0.25306234
B16: Earnings per share ($) | F16: ='Historical & Forecasted FS'!I52 -> 3.3817401 | G16: ='Historical & Forecasted FS'!J52 -> 5.7637568 | H16: ='Historical & Forecasted FS'!K52 -> 6.2598218 | I16: ='Historical & Forecasted FS'!L52 -> 6.2375961
B17: Dividends per share ($) | F17: ='Historical & Forecasted FS'!I55 -> 0.8 | G17: ='Historical & Forecasted FS'!J55 -> 0.85 | H17: ='Historical & Forecasted FS'!K55 -> 0.9 | I17: ='Historical & Forecasted FS'!L55 -> 0.94
B18: ='Ratio Analysis'!B28 -> Self Sustained Growth Rate | F18: ='Ratio Analysis'!I28 -> 0.56254166 | G18: ='Ratio Analysis'!J28 -> 1.2569939 | H18: ='Ratio Analysis'!K28 -> 1.502328 | I18: ='Ratio Analysis'!L28 -> 1.4603688
B20: Key Financial Ratios and Multiples | F20: ='Ratio Analysis'!I7 -> 2020 | G20: ='Ratio Analysis'!J7 -> 2021 | H20: ='Ratio Analysis'!K7 -> 2022 | I20: ='Ratio Analysis'!L7 -> 2023 | K20: Valuation
B21: ='Ratio Analysis'!B27 -> Return on Equity% | F21: ='Ratio Analysis'!I27 -> 0.73685562 | G21: ='Ratio Analysis'!J27 -> 1.4744333 | H21: ='Ratio Analysis'!K27 -> 1.7545929 | I21: ='Ratio Analysis'!L27 -> 1.7194951 | K21: Overvalued
B22: ='Ratio Analysis'!B25 -> Return on Capital Employed | F22: ='Ratio Analysis'!I25 -> 0.30338313 | G22: ='Ratio Analysis'!J25 -> 0.48309913 | H22: ='Ratio Analysis'!K25 -> 0.60087135 | I22: ='Ratio Analysis'!L25 -> 0.55144615
B23: ='Ratio Analysis'!B28 -> Self Sustained Growth Rate | F23: ='Ratio Analysis'!I28 -> 0.56254166 | G23: ='Ratio Analysis'!J28 -> 1.2569939 | H23: ='Ratio Analysis'!K28 -> 1.502328 | I23: ='Ratio Analysis'!L28 -> 1.4603688
B24: Debt/Equity | F24: ='Ratio Analysis'!I30 -> 1.8714397 | G24: ='Ratio Analysis'!J30 -> 2.1639246 | H24: ='Ratio Analysis'!K30 -> 2.6144616 | I24: ='Ratio Analysis'!L30 -> 1.994175 | L24: $ | M24: =DCF!E40 -> 124.93382
B25: ='Ratio Analysis'!B47 -> CFO/Total Assets | F25: ='Ratio Analysis'!I47 -> 0.24907993 | G25: ='Ratio Analysis'!J47 -> 0.29640287 | H25: ='Ratio Analysis'!K47 -> 0.34627716 | I25: ='Ratio Analysis'!L47 -> 0.31352334
B26: ='Ratio Analysis'!B35 -> Inventory Turnover | F26: ='Ratio Analysis'!I42 -> 8.7903178 | G26: ='Ratio Analysis'!J42 -> 9.1181021 | H26: ='Ratio Analysis'!K42 -> 9.4096741 | I26: ='Ratio Analysis'!L42 -> 9.610915
B28: MOAT | K28: 5 year Average Financials
B36: Insights | K36: 5 Year Average Revenue Distribution
R38: 2019 | S38: 2020 | T38: 2021 | U38: 2022 | V38: 2023 | W38: Avg
Q39: iPhone | R39: 142381 | S39: 137781 | T39: 191973 | U39: 205489 | V39: 200583 | W39: =AVERAGE(R39:V39) -> 175641.4
Q40: Mac | R40: 25740 | S40: 28622 | T40: 35190 | U40: 40177 | V40: 29357 | W40: =AVERAGE(R40:V40) -> 31817.2
Q41: iPad | R41: 21280 | S41: 23724 | T41: 31862 | U41: 29292 | V41: 28300 | W41: =AVERAGE(R41:V41) -> 26891.6
Q42: Wearables, Home and Accessories | R42: 24482 | S42: 30620 | T42: 38367 | U42: 41241 | V42: 39845 | W42: =AVERAGE(R42:V42) -> 34911
Q43: Services | R43: 46291 | S43: 53768 | T43: 68425 | U43: 78129 | V43: 85200 | W43: =AVERAGE(R43:V43) -> 66362.6
Q44: Total net sales | R44: 260174 | S44: 274515 | T44: 365817 | U44: 394328 | V44: 383285 | W44: =AVERAGE(R44:V44) -> 335623.8
K48: Shareholding Pattern
Q50: Institutional investors | R50: 0.5756
Q51: Insiders | R51: 0.0522
Q52: Public Companies and Individual investors | R52: =100%-R50-R51 -> 0.3722

Sheet Financials>

Sheet Historical & Forecasted FS
B4: in millions ($)
B5: ="Historical Financial Statement -"&'Data Sheet'!$A$4 -> Historical Financial Statement -Apple Inc. | N5: ="Forecasted Financial Statement " & "-" &'Data Sheet'!$A$4 -> Forecasted Financial Statement -Apple Inc.
B6: Years | C6: 2014 | D6: =C6+1 -> 2015 | E6: =D6+1 -> 2016 | F6: =E6+1 -> 2017 | G6: =F6+1 -> 2018 | H6: 2019 | I6: =H6+1 -> 2020 | J6: =I6+1 -> 2021 | K6: =J6+1 -> 2022 | L6: =K6+1 -> 2023 | M6: LTM | N6: =L6+1 -> 2024 | O6: =N6+1 -> 2025 | P6: =O6+1 -> 2026 | Q6: =P6+1 -> 2027 | R6: =Q6+1 -> 2028
A7: # | B7: Income Statement | C7: 1 | D7: 2 | E7: 3 | F7: 4 | G7: 5 | H7: 6 | I7: 7 | J7: 8 | K7: 9 | L7: 10 | N7: 11 | O7: 12 | P7: 13 | Q7: 14 | R7: 15
B8: Sales | C8: =IFERROR('Data Sheet'!B20,0) -> 182795 | D8: =IFERROR('Data Sheet'!C20,0) -> 233715 | E8: =IFERROR('Data Sheet'!D20,0) -> 215639 | F8: =IFERROR('Data Sheet'!E20,0) -> 229234 | G8: =IFERROR('Data Sheet'!F20,0) -> 265595 | H8: =IFERROR('Data Sheet'!G20,0) -> 260174 | I8: =IFERROR('Data Sheet'!H20,0) -> 274515 | J8: =IFERROR('Data Sheet'!I20,0) -> 365817 | ... L8: =IFERROR('Data Sheet'!K20,0) -> 383285 | M8: ='Data Sheet'!L20 -> 385706 | N8: =L8*(1+N9) -> 410114.95 | O8: =N8*(1+O9) -> 451126.45 | P8: =O8*(1+P9) -> 500750.35 | Q8: =P8*(1+Q9) -> 558336.64 | R8: =Q8*(1+R9) -> 625337.04
B9: Sales Growth | C9: - | D9: =D8/C8-1 -> 0.27856342 | E9: =E8/D8-1 -> -0.077342062 | F9: =F8/E8-1 -> 0.063045182 | G9: =G8/F8-1 -> 0.15861958 | H9: =H8/G8-1 -> -0.020410776 | I9: =I8/H8-1 -> 0.055120804 | J9: =J8/I8-1 -> 0.33259385 | K9: =K8/J8-1 -> 0.077937876 | ... M9: =M8/L8-1 -> 0.0063164486 | N9: 0.07 | O9: 0.1 | P9: 0.11 | Q9: 0.115 | R9: 0.12
B11: COGS | C11: =IFERROR('Data Sheet'!B22,0) -> 112258 | D11: =IFERROR('Data Sheet'!C22,0) -> 140089 | E11: =IFERROR('Data Sheet'!D22,0) -> 131376 | F11: =IFERROR('Data Sheet'!E22,0) -> 141048 | G11: =IFERROR('Data Sheet'!F22,0) -> 163756 | H11: =IFERROR('Data Sheet'!G22,0) -> 161782 | I11: =IFERROR('Data Sheet'!H22,0) -> 169559 | J11: =IFERROR('Data Sheet'!I22,0) -> 212981 | ... L11: =IFERROR('Data Sheet'!K22,0) -> 214137 | M11: ='Data Sheet'!L22 -> 212035 | N11: =N8*N12 -> 227203.68 | O11: =O8*O12 -> 249924.05 | P11: =P8*P12 -> 277415.7 | Q11: =Q8*Q12 -> 309318.5 | R11: =R8*R12 -> 346436.72
B12: COGS % Sales | C12: =C11/C8 -> 0.61411964 | D12: =D11/D8 -> 0.59940098 | E12: =E11/E8 -> 0.60924044 | F12: =F11/F8 -> 0.6153014 | G12: =G11/G8 -> 0.61656281 | H12: =H11/H8 -> 0.62182232 | I12: =I11/I8 -> 0.61766752 | J12: =J11/J8 -> 0.5822064 | ... M12: =M11/M8 -> 0.54973218 | N12: 0.554 | O12: 0.554 | P12: 0.554 | Q12: 0.554 | R12: 0.554
B14: Gross Profit | C14: =IFERROR(C8-C11,0) -> 70537 | D14: =IFERROR(D8-D11,0) -> 93626 | E14: =IFERROR(E8-E11,0) -> 84263 | F14: =IFERROR(F8-F11,0) -> 88186 | G14: =IFERROR(G8-G11,0) -> 101839 | H14: =IFERROR(H8-H11,0) -> 98392 | I14: =IFERROR(I8-I11,0) -> 104956 | J14: =IFERROR(J8-J11,0) -> 152836 | ... R14: =IFERROR(R8-R11,0) -> 278900.32
B15: Gross Profit % Sales | C15: =C14/C8 -> 0.38588036 | D15: =D14/D8 -> 0.40059902 | E15: =E14/E8 -> 0.39075956 | F15: =F14/F8 -> 0.3846986 | G15: =G14/G8 -> 0.38343719 | H15: =H14/H8 -> 0.37817768 | I15: =I14/I8 -> 0.38233248 | J15: =J14/J8 -> 0.4177936 | ... R15: =R14/R8 -> 0.446
B17: SG&A Expenses | C17: =IFERROR('Data Sheet'!B25,0) -> 11993 | D17: =IFERROR('Data Sheet'!C25,0) -> 14329 | E17: =IFERROR('Data Sheet'!D25,0) -> 14194 | F17: =IFERROR('Data Sheet'!E25,0) -> 15261 | G17: =IFERROR('Data Sheet'!F25,0) -> 16705 | H17: =IFERROR('Data Sheet'!G25,0) -> 18245 | I17: =IFERROR('Data Sheet'!H25,0) -> 19916 | J17: =IFERROR('Data Sheet'!I25,0) -> 21973 | ... M17: =IFERROR('Data Sheet'!L25,0) -> 25111 | N17: =FORECAST(N7,$C$17:$L$17,$C$7:$L$7) -> 26471.067 | O17: =FORECAST(O7,$C$17:$L$17,$C$7:$L$7) -> 27963.224 | P17: =FORECAST(P7,$C$17:$L$17,$C$7:$L$7) -> 29455.382 | Q17: =FORECAST(Q7,$C$17:$L$17,$C$7:$L$7) -> 30947.539 | R17: =FORECAST(R7,$C$17:$L$17,$C$7:$L$7) -> 32439.697
B18: SG&A % Sales | C18: =C17/C8 -> 0.065609016 | D18: =D17/D8 -> 0.061309715 | E18: =E17/E8 -> 0.065822973 | F18: =F17/F8 -> 0.066573894 | G18: =G17/G8 -> 0.062896515 | H18: =H17/H8 -> 0.070126146 | I18: =I17/I8 -> 0.07254977 | J18: =J17/J8 -> 0.060065552 | ... R18: =R17/R8 -> 0.05187554
B20: R&D Expenses | C20: =IFERROR('Data Sheet'!B26,0) -> 6041 | D20: =IFERROR('Data Sheet'!C26,0) -> 8067 | E20: =IFERROR('Data Sheet'!D26,0) -> 10045 | F20: =IFERROR('Data Sheet'!E26,0) -> 11581 | G20: =IFERROR('Data Sheet'!F26,0) -> 14236 | H20: =IFERROR('Data Sheet'!G26,0) -> 16217 | I20: =IFERROR('Data Sheet'!H26,0) -> 18752 | J20: =IFERROR('Data Sheet'!I26,0) -> 21914 | ... M20: =IFERROR('Data Sheet'!L26,0) -> 29902 | N20: =FORECAST(N7,$C$20:$L$20,$C$7:$L$7) -> 30468.333 | O20: =FORECAST(O7,$C$20:$L$20,$C$7:$L$7) -> 33044.048 | P20: =FORECAST(P7,$C$20:$L$20,$C$7:$L$7) -> 35619.764 | Q20: =FORECAST(Q7,$C$20:$L$20,$C$7:$L$7) -> 38195.479 | R20: =FORECAST(R7,$C$20:$L$20,$C$7:$L$7) -> 40771.194
B21: R&D % Sales | C21: =C20/C8 -> 0.03304795 | D21: =D20/D8 -> 0.034516398 | E21: =E20/E8 -> 0.046582483 | F21: =F20/F8 -> 0.050520429 | G21: =G20/G8 -> 0.053600407 | H21: =H20/H8 -> 0.062331363 | I21: =I20/I8 -> 0.068309564 | J21: =J20/J8 -> 0.059904269 | ... R21: =R20/R8 -> 0.065198751
B23: EBIT | C23: =IFERROR(C14-SUM(C20,C17),0) -> 52503 | D23: =IFERROR(D14-SUM(D20,D17),0) -> 71230 | E23: =IFERROR(E14-SUM(E20,E17),0) -> 60024 | F23: =IFERROR(F14-SUM(F20,F17),0) -> 61344 | G23: =IFERROR(G14-SUM(G20,G17),0) -> 70898 | H23: =IFERROR(H14-SUM(H20,H17),0) -> 63930 | I23: =IFERROR(I14-SUM(I20,I17),0) -> 66288 | J23: =IFERROR(J14-SUM(J20,J17),0) -> 108949 | ... R23: =IFERROR(R14-SUM(R20,R17),0) -> 205689.43
B24: EBIT Margins | C24: =C23/C8 -> 0.28722339 | D24: =D23/D8 -> 0.30477291 | E24: =E23/E8 -> 0.2783541 | F24: =F23/F8 -> 0.26760428 | G24: =G23/G8 -> 0.26694027 | H24: =H23/H8 -> 0.24572017 | I24: =I23/I8 -> 0.24147314 | J24: =J23/J8 -> 0.29782378 | ... R24: =R23/R8 -> 0.32892571
B26: Dep & Amm | C26: =IFERROR('Data Sheet'!B216,0) -> 6846 | D26: =IFERROR('Data Sheet'!C216,0) -> 9957 | E26: =IFERROR('Data Sheet'!D216,0) -> 10505 | F26: =IFERROR('Data Sheet'!E216,0) -> 10157 | G26: =IFERROR('Data Sheet'!F216,0) -> 10903 | H26: =IFERROR('Data Sheet'!G216,0) -> 12547 | I26: =IFERROR('Data Sheet'!H216,0) -> 11056 | J26: =IFERROR('Data Sheet'!I216,0) -> 11284 | ... M26: =IFERROR('Data Sheet'!L216,0) -> 11451 | N26: =FORECAST(N7,$C$26:$L$26,$C$7:$L$7) -> 12531.867 | O26: =FORECAST(O7,$C$26:$L$26,$C$7:$L$7) -> 12885.333 | P26: 12885 | Q26: 12885 | R26: 12885
B27: Dep & Amm % Sales | C27: =C26/C8 -> 0.03745179 | D27: =D26/D8 -> 0.042603171 | E27: =E26/E8 -> 0.048715678 | F27: =F26/F8 -> 0.044308436 | G27: =G26/G8 -> 0.041051225 | H27: =H26/H8 -> 0.048225418 | I27: =I26/I8 -> 0.040274666 | J27: =J26/J8 -> 0.030846024 | ... R27: =R26/R8 -> 0.020604888
B29: EBITDA | C29: =IFERROR(C23+C26,0) -> 59349 | D29: =IFERROR(D23+D26,0) -> 81187 | E29: =IFERROR(E23+E26,0) -> 70529 | F29: =IFERROR(F23+F26,0) -> 71501 | G29: =IFERROR(G23+G26,0) -> 81801 | H29: =IFERROR(H23+H26,0) -> 76477 | I29: =IFERROR(I23+I26,0) -> 77344 | J29: =IFERROR(J23+J26,0) -> 120233 | ... R29: =IFERROR(R23+R26,0) -> 218574.43
B30: EBITDA Margins | C30: =C29/C8 -> 0.32467518 | D30: =D29/D8 -> 0.34737608 | E30: =E29/E8 -> 0.32706978 | F30: =F29/F8 -> 0.31191272 | G30: =G29/G8 -> 0.30799149 | H30: =H29/H8 -> 0.29394559 | I30: =I29/I8 -> 0.28174781 | J30: =J29/J8 -> 0.3286698 | ... R30: =R29/R8 -> 0.3495306
B32: Other operating expenses | C32: =IFERROR('Data Sheet'!B38,0) -> -431 | D32: =IFERROR('Data Sheet'!C38,0) -> -903 | E32: =IFERROR('Data Sheet'!D38,0) -> -1195 | F32: =IFERROR('Data Sheet'!E38,0) -> -133 | G32: =IFERROR('Data Sheet'!F38,0) -> -441 | H32: =IFERROR('Data Sheet'!G38,0) -> 422 | I32: =IFERROR('Data Sheet'!H38,0) -> -87 | J32: =IFERROR('Data Sheet'!I38,0) -> 60 | ... M32: =IFERROR('Data Sheet'!L38,0) -> -39 | N32: =FORECAST(N7,$C$32:$L$32,$C$7:$L$7) -> 82.933333 | O32: =FORECAST(O7,$C$32:$L$32,$C$7:$L$7) -> 158.33939 | P32: =FORECAST(P7,$C$32:$L$32,$C$7:$L$7) -> 233.74545 | Q32: =FORECAST(Q7,$C$32:$L$32,$C$7:$L$7) -> 309.15152 | R32: =FORECAST(R7,$C$32:$L$32,$C$7:$L$7) -> 384.55758
B33: Other Op Ex % Sales | C33: =C32/C11 -> -0.00383937 | D33: =D32/D11 -> -0.0064459022 | E33: =E32/E11 -> -0.0090960297 | F33: =F32/F11 -> -0.00094294141 | G33: =G32/G11 -> -0.0026930311 | H33: =H32/H11 -> 0.0026084484 | I33: =I32/I11 -> -0.00051309574 | J33: =J32/J11 -> 0.00028171527 | ... R33: =R32/R11 -> 0.001110037
B35: Net Interest Expense | C35: =IFERROR('Data Sheet'!B36,0) -> 1411 | D35: =IFERROR('Data Sheet'!C36,0) -> 2188 | E35: =IFERROR('Data Sheet'!D36,0) -> 2543 | F35: =IFERROR('Data Sheet'!E36,0) -> 2878 | G35: =IFERROR('Data Sheet'!F36,0) -> 2446 | H35: =IFERROR('Data Sheet'!G36,0) -> 1385 | I35: =IFERROR('Data Sheet'!H36,0) -> 890 | J35: =IFERROR('Data Sheet'!I36,0) -> 198 | ... M35: =IFERROR('Data Sheet'!L36,0) -> -183 | N35: =FORECAST(N7,$C$35:$L$35,$C$7:$L$7) -> -273.46667 | O35: =FORECAST(O7,$C$35:$L$35,$C$7:$L$7) -> -571.3697 | P35: =FORECAST(P7,$C$35:$L$35,$C$7:$L$7) -> -869.27273 | Q35: =FORECAST(Q7,$C$35:$L$35,$C$7:$L$7) -> -1167.1758 | R35: =FORECAST(R7,$C$35:$L$35,$C$7:$L$7) -> -1465.0788
B36: Interest % Sales | C36: =C35/C8 -> 0.0077190295 | D36: =D35/D8 -> 0.0093618296 | E36: =E35/E8 -> 0.011792858 | F36: =F35/F8 -> 0.012554857 | G36: =G35/G8 -> 0.0092095107 | H36: =H35/H8 -> 0.0053233605 | I36: =I35/I8 -> 0.0032420815 | J36: =J35/J8 -> 0.00054125423 | ... R36: =R35/R8 -> -0.0023428626
B38: Dep & Amm | C38: =IFERROR('Data Sheet'!B216,0) -> 6846 | D38: =IFERROR('Data Sheet'!C216,0) -> 9957 | E38: =IFERROR('Data Sheet'!D216,0) -> 10505 | F38: =IFERROR('Data Sheet'!E216,0) -> 10157 | G38: =IFERROR('Data Sheet'!F216,0) -> 10903 | H38: =IFERROR('Data Sheet'!G216,0) -> 12547 | I38: =IFERROR('Data Sheet'!H216,0) -> 11056 | J38: =IFERROR('Data Sheet'!I216,0) -> 11284 | ... M38: =IFERROR('Data Sheet'!L216,0) -> 11451 | N38: =FORECAST(N7,$C$38:$L$38,$C$7:$L$7) -> 12531.867 | O38: =FORECAST(O7,$C$38:$L$38,$C$7:$L$7) -> 12885.333 | P38: =FORECAST(P7,$C$38:$L$38,$C$7:$L$7) -> 13238.8 | Q38: =FORECAST(Q7,$C$38:$L$38,$C$7:$L$7) -> 13592.267 | R38: =FORECAST(R7,$C$38:$L$38,$C$7:$L$7) -> 13945.733
B39: Dep & Amm % Sales | C39: =C38/C8 -> 0.03745179 | D39: =D38/D8 -> 0.042603171 | E39: =E38/E8 -> 0.048715678 | F39: =F38/F8 -> 0.044308436 | G39: =G38/G8 -> 0.041051225 | H39: =H38/H8 -> 0.048225418 | I39: =I38/I8 -> 0.040274666 | J39: =J38/J8 -> 0.030846024 | ... R39: =R38/R8 -> 0.022301147
B41: EBT | C41: =IFERROR(C29+C32+C35-C38,0) -> 53483 | D41: =IFERROR(D29+D32+D35-D38,0) -> 72515 | E41: =IFERROR(E29+E32+E35-E38,0) -> 61372 | F41: =IFERROR(F29+F32+F35-F38,0) -> 64089 | G41: =IFERROR(G29+G32+G35-G38,0) -> 72903 | H41: =IFERROR(H29+H32+H35-H38,0) -> 65737 | I41: =IFERROR(I29+I32+I35-I38,0) -> 67091 | J41: =IFERROR(J29+J32+J35-J38,0) -> 109207 | ... R41: =IFERROR(R29+R32+R35-R38,0) -> 203548.18
B42: EBT Margins | C42: =C41/C8 -> 0.29258459 | D42: =D41/D8 -> 0.31027106 | E42: =E41/E8 -> 0.28460529 | F42: =F41/F8 -> 0.27957895 | G42: =G41/G8 -> 0.27448935 | H42: =H41/H8 -> 0.25266552 | I42: =I41/I8 -> 0.2443983 | J42: =J41/J8 -> 0.29852905 | ... R42: =R41/R8 -> 0.32550155
B44: Tax | C44: =IFERROR('Data Sheet'!B45,0) -> 13973 | D44: =IFERROR('Data Sheet'!C45,0) -> 19121 | E44: =IFERROR('Data Sheet'!D45,0) -> 15685 | F44: =IFERROR('Data Sheet'!E45,0) -> 15738 | G44: =IFERROR('Data Sheet'!F45,0) -> 13372 | H44: =IFERROR('Data Sheet'!G45,0) -> 10481 | I44: =IFERROR('Data Sheet'!H45,0) -> 9680 | J44: =IFERROR('Data Sheet'!I45,0) -> 14527 | ... M44: =IFERROR('Data Sheet'!L45,0) -> 17523 | N44: =N41*N45 -> 18515.012 | O44: =O41*O45 -> 20575.924 | P44: =P41*P45 -> 23150.171 | Q44: =Q41*Q45 -> 26247.208 | R44: =R41*R45 -> 29962.291
B45: Effective Tax Rate | C45: =C44/C41 -> 0.26126059 | D45: =D44/D41 -> 0.26368338 | E45: =E44/E41 -> 0.25557257 | F45: =F44/F41 -> 0.24556476 | G45: =G44/G41 -> 0.18342181 | H45: =H44/H41 -> 0.15943837 | I45: =I44/I41 -> 0.14428165 | J45: =J44/J41 -> 0.13302261 | ... M45: =M44/M41 -> 0.14795333 | N45: 0.1472 | O45: 0.1472 | P45: 0.1472 | Q45: 0.1472 | R45: 0.1472
B47: Net profit | C47: =IFERROR(C41-C44,0) -> 39510 | D47: =IFERROR(D41-D44,0) -> 53394 | E47: =IFERROR(E41-E44,0) -> 45687 | F47: =IFERROR(F41-F44,0) -> 48351 | G47: =IFERROR(G41-G44,0) -> 59531 | H47: =IFERROR(H41-H44,0) -> 55256 | I47: =IFERROR(I41-I44,0) -> 57411 | J47: =IFERROR(J41-J44,0) -> 94680 | ... R47: =IFERROR(R41-R44,0) -> 173585.88
B48: Net Margins | C48: =C47/C8 -> 0.21614377 | D48: =D47/D8 -> 0.22845774 | E48: =E47/E8 -> 0.21186798 | F48: =F47/F8 -> 0.21092421 | G48: =G47/G8 -> 0.22414202 | H48: =H47/H8 -> 0.21238095 | I48: =I47/I8 -> 0.20913611 | J48: =J47/J8 -> 0.25881793 | ... R48: =R47/R8 -> 0.27758772
B50: No. of Equity Shares | C50: =IFERROR('Data Sheet'!B183,0) -> 23464.644 | D50: =IFERROR('Data Sheet'!C183,0) -> 22315.012 | E50: =IFERROR('Data Sheet'!D183,0) -> 21344.664 | F50: =IFERROR('Data Sheet'!E183,0) -> 20504.804 | G50: =IFERROR('Data Sheet'!F183,0) -> 19019.944 | H50: =IFERROR('Data Sheet'!G183,0) -> 17772.944 | I50: =IFERROR('Data Sheet'!H183,0) -> 16976.763 | J50: =IFERROR('Data Sheet'!I183,0) -> 16426.786 | ... M50: =IFERROR('Data Sheet'!L183,0) -> 15460.223 | N50: 15460 | O50: =N50 -> 15460 | P50: =O50 -> 15460 | Q50: =P50 -> 15460 | R50: =Q50 -> 15460
B52: Earnings per share | C52: =IFERROR(C47/C50,0) -> 1.6838099 | D52: =IFERROR(D47/D50,0) -> 2.392739 | E52: =IFERROR(E47/E50,0) -> 2.1404413 | F52: =IFERROR(F47/F50,0) -> 2.3580328 | G52: =IFERROR(G47/G50,0) -> 3.1299251 | H52: =IFERROR(H47/H50,0) -> 3.1089953 | I52: =IFERROR(I47/I50,0) -> 3.3817401 | J52: =IFERROR(J47/J50,0) -> 5.7637568 | ... M52: =IFERROR(M47/M50,0) -> 6.5272668 | N52: =N47/DCF!$E$39 -> 6.93607 | O52: =O47/DCF!$E$39 -> 7.7081259 | P52: =P47/DCF!$E$39 -> 8.6724872 | Q52: =Q47/DCF!$E$39 -> 9.8326949 | R52: =R47/DCF!$E$39 -> 11.224435
B53: EPS Growth % | C53: - | D53: =D52/C52-1 -> 0.42102681 | E53: =E52/D52-1 -> -0.10544307 | F53: =F52/E52-1 -> 0.10165731 | G53: =G52/F52-1 -> 0.32734588 | H53: =H52/G52-1 -> -0.0066869835 | I53: =I52/H52-1 -> 0.087727617 | J53: =J52/I52-1 -> 0.70437605 | K53: =K52/J52-1 -> 0.086066263 | ... M53: =M52/L52-1 -> 0.046439472 | N53: =N52/L52-1 -> 0.11197805 | O53: =O52/N52-1 -> 0.11131029 | P53: =P52/O52-1 -> 0.12510969 | Q53: =Q52/P52-1 -> 0.13378028 | R53: =R52/Q52-1 -> 0.14154206
B55: Dividend per share | C55: =IFERROR('Data Sheet'!B72,0) -> 0.46 | D55: =IFERROR('Data Sheet'!C72,0) -> 0.5 | E55: =IFERROR('Data Sheet'!D72,0) -> 0.55 | F55: =IFERROR('Data Sheet'!E72,0) -> 0.6 | G55: =IFERROR('Data Sheet'!F72,0) -> 0.68 | H55: =IFERROR('Data Sheet'!G72,0) -> 0.75 | I55: =IFERROR('Data Sheet'!H72,0) -> 0.8 | J55: =IFERROR('Data Sheet'!I72,0) -> 0.85 | ... M55: =IFERROR('Data Sheet'!L72,0) -> 0.95 | N55: 0.97 | O55: 0.98 | P55: 0.99 | Q55: =P55 -> 0.99 | R55: =Q55 -> 0.99
B56: Dividend payout ratio | C56: =IFERROR(C55/C52,0) -> 0.27318998 | D56: =IFERROR(D55/D52,0) -> 0.20896554 | E56: =IFERROR(E55/E52,0) -> 0.25695636 | F56: =IFERROR(F55/F52,0) -> 0.25444939 | G56: =IFERROR(G55/G52,0) -> 0.2172576 | H56: =IFERROR(H55/H52,0) -> 0.24123549 | I56: =IFERROR(I55/I52,0) -> 0.2365646 | J56: =IFERROR(J55/J52,0) -> 0.14747326 | ... R56: =IFERROR(R55/R52,0) -> 0.088200432
B58: Retained Earnings | C58: =IFERROR(1-C56,0) -> 0.72681002 | D58: =IFERROR(1-D56,0) -> 0.79103446 | E58: =IFERROR(1-E56,0) -> 0.74304364 | F58: =IFERROR(1-F56,0) -> 0.74555061 | G58: =IFERROR(1-G56,0) -> 0.7827424 | H58: =IFERROR(1-H56,0) -> 0.75876451 | I58: =IFERROR(1-I56,0) -> 0.7634354 | J58: =IFERROR(1-J56,0) -> 0.85252674 | ... R58: =IFERROR(1-R56,0) -> 0.91179957
B60: in millions ($)
B61: ="Historical Financial Statement -"&'Data Sheet'!$A$4 -> Historical Financial Statement -Apple Inc. | N61: ="Forecasted Financial Statement " & "-" &'Data Sheet'!$A$4 -> Forecasted Financial Statement -Apple Inc.
...

Sheet Specific Forecasts
B6: ="Sales Forecasting -"&'Data Sheet'!$A$4 -> Sales Forecasting -Apple Inc. | G6: ="EBITDA Forecasting -"&'Data Sheet'!$A$4 -> EBITDA Forecasting -Apple Inc. | L6: ="EPS Forecasting -"&'Data Sheet'!$A$4 -> EPS Forecasting -Apple Inc.
B7: Year Weight | C7: Year | D7: Sales | E7: Sales Growth | G7: Year Weight | H7: Year | I7: Sales | J7: EBITDA Growth | L7: Year Weight | M7: Year | N7: Sales | O7: EPS Growth
B8: 1 | C8: 2014 | D8: {=TRANSPOSE('Historical & Forecasted FS'!C8:L8)} -> 182795 | G8: 1 | H8: 2014 | I8: {=TRANSPOSE('Historical & Forecasted FS'!C29:L29)} -> 59349 | L8: 1 | M8: 2014 | N8: {=TRANSPOSE('Historical & Forecasted FS'!C52:L52)} -> 1.6838099
B9: =B8+1 -> 2 | C9: =C8+1 -> 2015 | D9: 233715 | E9: =D9/D8-1 -> 0.27856342 | G9: =G8+1 -> 2 | H9: =H8+1 -> 2015 | I9: 81187 | J9: =I9/I8-1 -> 0.36795902 | L9: =L8+1 -> 2 | M9: =M8+1 -> 2015 | N9: 2.392739 | O9: =N9/N8-1 -> 0.42102681
B10: =B9+1 -> 3 | C10: =C9+1 -> 2016 | D10: 215639 | E10: =D10/D9-1 -> -0.077342062 | G10: =G9+1 -> 3 | H10: =H9+1 -> 2016 | I10: 70529 | J10: =I10/I9-1 -> -0.13127717 | L10: =L9+1 -> 3 | M10: =M9+1 -> 2016 | N10: 2.1404413 | O10: =N10/N9-1 -> -0.10544307
B11: =B10+1 -> 4 | C11: =C10+1 -> 2017 | D11: 229234 | E11: =D11/D10-1 -> 0.063045182 | G11: =G10+1 -> 4 | H11: =H10+1 -> 2017 | I11: 71501 | J11: =I11/I10-1 -> 0.013781565 | L11: =L10+1 -> 4 | M11: =M10+1 -> 2017 | N11: 2.3580328 | O11: =N11/N10-1 -> 0.10165731
B12: =B11+1 -> 5 | C12: =C11+1 -> 2018 | D12: 265595 | E12: =D12/D11-1 -> 0.15861958 | G12: =G11+1 -> 5 | H12: =H11+1 -> 2018 | I12: 81801 | J12: =I12/I11-1 -> 0.14405393 | L12: =L11+1 -> 5 | M12: =M11+1 -> 2018 | N12: 3.1299251 | O12: =N12/N11-1 -> 0.32734588
B13: =B12+1 -> 6 | C13: =C12+1 -> 2019 | D13: 260174 | E13: =D13/D12-1 -> -0.020410776 | G13: =G12+1 -> 6 | H13: =H12+1 -> 2019 | I13: 76477 | J13: =I13/I12-1 -> -0.065084779 | L13: =L12+1 -> 6 | M13: =M12+1 -> 2019 | N13: 3.1089953 | O13: =N13/N12-1 -> -0.0066869835
B14: =B13+1 -> 7 | C14: =C13+1 -> 2020 | D14: 274515 | E14: =D14/D13-1 -> 0.055120804 | G14: =G13+1 -> 7 | H14: =H13+1 -> 2020 | I14: 77344 | J14: =I14/I13-1 -> 0.011336742 | L14: =L13+1 -> 7 | M14: =M13+1 -> 2020 | N14: 3.3817401 | O14: =N14/N13-1 -> 0.087727617
B15: =B14+1 -> 8 | C15: =C14+1 -> 2021 | D15: 365817 | E15: =D15/D14-1 -> 0.33259385 | G15: =G14+1 -> 8 | H15: =H14+1 -> 2021 | I15: 120233 | J15: =I15/I14-1 -> 0.55452265 | L15: =L14+1 -> 8 | M15: =M14+1 -> 2021 | N15: 5.7637568 | O15: =N15/N14-1 -> 0.70437605
B16: =B15+1 -> 9 | C16: =C15+1 -> 2022 | D16: 394328 | E16: =D16/D15-1 -> 0.077937876 | G16: =G15+1 -> 9 | H16: =H15+1 -> 2022 | I16: 130541 | J16: =I16/I15-1 -> 0.085733534 | L16: =L15+1 -> 9 | M16: =M15+1 -> 2022 | N16: 6.2598218 | O16: =N16/N15-1 -> 0.086066263
B17: =B16+1 -> 10 | C17: =C16+1 -> 2023 | D17: 383285 | E17: =D17/D16-1 -> -0.028004605 | G17: =G16+1 -> 10 | H17: =H16+1 -> 2023 | I17: 125820 | J17: =I17/I16-1 -> -0.036164883 | L17: =L16+1 -> 10 | M17: =M16+1 -> 2023 | N17: 6.2375961 | O17: =N17/N16-1 -> -0.003550537
B18: 11 | C18: 2024 | D18: =FORECAST(B18,$D$8:$D$17,$B$8:$B$17) -> 407510.13 | E18: =D18/D17-1 -> 0.063203969 | G18: 11 | H18: 2024 | I18: =FORECAST(G18,$I$8:$I$17,$G$8:$G$17) -> 129626.27 | J18: =I18/I17-1 -> 0.030251682 | L18: 11 | M18: 2024 | N18: =FORECAST(L18,$N$8:$N$17,$L$8:$L$17) -> 6.6197 | O18: =N18/N17-1 -> 0.061258198
B19: 12 | C19: 2025 | D19: =FORECAST(B19,$D$8:$D$17,$B$8:$B$17) -> 430601.12 | E19: =D19/D18-1 -> 0.056663592 | G19: 12 | H19: 2025 | I19: =FORECAST(G19,$I$8:$I$17,$G$8:$G$17) -> 136925.92 | J19: =I19/I18-1 -> 0.056313035 | L19: 12 | M19: 2025 | N19: =FORECAST(L19,$N$8:$N$17,$L$8:$L$17) -> 7.1604299 | O19: =N19/N18-1 -> 0.081684948
B20: 13 | C20: 2026 | D20: =FORECAST(B20,$D$8:$D$17,$B$8:$B$17) -> 453692.11 | E20: =D20/D19-1 -> 0.053625006 | G20: 13 | H20: 2026 | I20: =FORECAST(G20,$I$8:$I$17,$G$8:$G$17) -> 144225.56 | J20: =I20/I19-1 -> 0.053310934 | L20: 13 | M20: 2026 | N20: =FORECAST(L20,$N$8:$N$17,$L$8:$L$17) -> 7.7011597 | O20: =N20/N19-1 -> 0.075516395
B21: 14 | C21: 2027 | D21: =FORECAST(B21,$D$8:$D$17,$B$8:$B$17) -> 476783.1 | E21: =D21/D20-1 -> 0.050895723 | G21: 14 | H21: 2027 | I21: =FORECAST(G21,$I$8:$I$17,$G$8:$G$17) -> 151525.21 | J21: =I21/I20-1 -> 0.050612723 | L21: 14 | M21: 2027 | N21: =FORECAST(L21,$N$8:$N$17,$L$8:$L$17) -> 8.2418896 | O21: =N21/N20-1 -> 0.070214081
B22: 15 | C22: 2028 | D22: =FORECAST(B22,$D$8:$D$17,$B$8:$B$17) -> 499874.08 | E22: =D22/D21-1 -> 0.048430802 | G22: 15 | H22: 2028 | I22: =FORECAST(G22,$I$8:$I$17,$G$8:$G$17) -> 158824.86 | J22: =I22/I21-1 -> 0.048174481 | L22: 15 | M22: 2028 | N22: =FORECAST(L22,$N$8:$N$17,$L$8:$L$17) -> 8.7826194 | O22: =N22/N21-1 -> 0.06560751

Sheet Ratio Analysis
B6: ="Ratio Analysis -"&'Data Sheet'!A4 -> Ratio Analysis -Apple Inc. | N6: Based on FY - 10 year | P6: Apple Inc. Based on FY - 5year | Q6: S&P 500 - IT sector Based on CY - 5year
B7: Years | C7: 2014 | D7: =C7+1 -> 2015 | E7: =D7+1 -> 2016 | F7: =E7+1 -> 2017 | G7: =F7+1 -> 2018 | H7: 2019 | I7: =H7+1 -> 2020 | J7: =I7+1 -> 2021 | K7: =J7+1 -> 2022 | L7: =K7+1 -> 2023 | N7: Mean | O7: Median | P7: Mean | Q7: Mean
B9: ="Sales" & " " & "Growth" -> Sales Growth | C9: - | D9: =IFERROR('Historical & Forecasted FS'!D9,0) -> 0.27856342 | E9: =IFERROR('Historical & Forecasted FS'!E9,0) -> -0.077342062 | F9: =IFERROR('Historical & Forecasted FS'!F9,0) -> 0.063045182 | G9: =IFERROR('Historical & Forecasted FS'!G9,0) -> 0.15861958 | H9: =IFERROR('Historical & Forecasted FS'!H9,0) -> -0.020410776 | I9: =IFERROR('Historical & Forecasted FS'!I9,0) -> 0.055120804 | J9: =IFERROR('Historical & Forecasted FS'!J9,0) -> 0.33259385 | K9: =IFERROR('Historical & Forecasted FS'!K9,0) -> 0.077937876 | L9: =IFERROR('Historical & Forecasted FS'!L9,0) -> -0.028004605 | N9: =IFERROR(AVERAGE(D9:L9),0) -> 0.093347029 | O9: =IFERROR(MEDIAN(D9:L9),0) -> 0.063045182 | P9: =AVERAGE(H9:L9) -> 0.083447429 | Q9: 0.0878
B10: ="EBITDA" & " " & "Growth" -> EBITDA Growth | C10: - | D10: =IFERROR('Historical & Forecasted FS'!D29/'Historical & Forecasted FS'!C29-1,0) -> 0.36795902 | E10: =IFERROR('Historical & Forecasted FS'!E29/'Historical & Forecasted FS'!D29-1,0) -> -0.13127717 | F10: =IFERROR('Historical & Forecasted FS'!F29/'Historical & Forecasted FS'!E29-1,0) -> 0.013781565 | G10: =IFERROR('Historical & Forecasted FS'!G29/'Historical & Forecasted FS'!F29-1,0) -> 0.14405393 | H10: =IFERROR('Historical & Forecasted FS'!H29/'Historical & Forecasted FS'!G29-1,0) -> -0.065084779 | I10: =IFERROR('Historical & Forecasted FS'!I29/'Historical & Forecasted FS'!H29-1,0) -> 0.011336742 | J10: =IFERROR('Historical & Forecasted FS'!J29/'Historical & Forecasted FS'!I29-1,0) -> 0.55452265 | K10: =IFERROR('Historical & Forecasted FS'!K29/'Historical & Forecasted FS'!J29-1,0) -> 0.085733534 | L10: =IFERROR('Historical & Forecasted FS'!L29/'Historical & Forecasted FS'!K29-1,0) -> -0.036164883 | N10: =IFERROR(AVERAGE(D10:L10),0) -> 0.10498451 | O10: =IFERROR(MEDIAN(D10:L10),0) -> 0.013781565 | P10: =AVERAGE(H10:L10) -> 0.11006865 | Q10: 0.0974
B11: ="EBIT" & " " & "Growth" -> EBIT Growth | C11: - | D11: =IFERROR('Historical & Forecasted FS'!D23/'Historical & Forecasted FS'!C23-1,0) -> 0.35668438 | E11: =IFERROR('Historical & Forecasted FS'!E23/'Historical & Forecasted FS'!D23-1,0) -> -0.15732135 | F11: =IFERROR('Historical & Forecasted FS'!F23/'Historical & Forecasted FS'!E23-1,0) -> 0.021991204 | G11: =IFERROR('Historical & Forecasted FS'!G23/'Historical & Forecasted FS'!F23-1,0) -> 0.15574465 | H11: =IFERROR('Historical & Forecasted FS'!H23/'Historical & Forecasted FS'!G23-1,0) -> -0.098282039 | I11: =IFERROR('Historical & Forecasted FS'!I23/'Historical & Forecasted FS'!H23-1,0) -> 0.036884092 | J11: =IFERROR('Historical & Forecasted FS'!J23/'Historical & Forecasted FS'!I23-1,0) -> 0.64357048 | K11: =IFERROR('Historical & Forecasted FS'!K23/'Historical & Forecasted FS'!J23-1,0) -> 0.096265225 | L11: =IFERROR('Historical & Forecasted FS'!L23/'Historical & Forecasted FS'!K23-1,0) -> -0.04300175 | N11: =IFERROR(AVERAGE(D11:L11),0) -> 0.11250388 | O11: =IFERROR(MEDIAN(D11:L11),0) -> 0.036884092 | P11: =AVERAGE(H11:L11) -> 0.1270872 | Q11: 0.1016
B12: ="Net Profit" & " " & "Growth" -> Net Profit Growth | C12: - | D12: =IFERROR('Historical & Forecasted FS'!D47/'Historical & Forecasted FS'!C47-1,0) -> 0.35140471 | E12: =IFERROR('Historical & Forecasted FS'!E47/'Historical & Forecasted FS'!D47-1,0) -> -0.14434206 | F12: =IFERROR('Historical & Forecasted FS'!F47/'Historical & Forecasted FS'!E47-1,0) -> 0.058309804 | G12: =IFERROR('Historical & Forecasted FS'!G47/'Historical & Forecasted FS'!F47-1,0) -> 0.23122583 | H12: =IFERROR('Historical & Forecasted FS'!H47/'Historical & Forecasted FS'!G47-1,0) -> -0.071811325 | I12: =IFERROR('Historical & Forecasted FS'!I47/'Historical & Forecasted FS'!H47-1,0) -> 0.03900029 | J12: =IFERROR('Historical & Forecasted FS'!J47/'Historical & Forecasted FS'!I47-1,0) -> 0.64916131 | K12: =IFERROR('Historical & Forecasted FS'!K47/'Historical & Forecasted FS'!J47-1,0) -> 0.054108576 | L12: =IFERROR('Historical & Forecasted FS'!L47/'Historical & Forecasted FS'!K47-1,0) -> -0.028135427 | N12: =IFERROR(AVERAGE(D12:L12),0) -> 0.12654686 | O12: =IFERROR(MEDIAN(D12:L12),0) -> 0.054108576 | P12: =AVERAGE(H12:L12) -> 0.12846468 | Q12: 0.1037
B13: ="Dividend" & " " & "Growth" -> Dividend Growth | C13: - | D13: =IFERROR('Historical & Forecasted FS'!D55/'Historical & Forecasted FS'!C55-1,0) -> 0.086956522 | E13: =IFERROR('Historical & Forecasted FS'!E55/'Historical & Forecasted FS'!D55-1,0) -> 0.1 | F13: =IFERROR('Historical & Forecasted FS'!F55/'Historical & Forecasted FS'!E55-1,0) -> 0.090909091 | G13: =IFERROR('Historical & Forecasted FS'!G55/'Historical & Forecasted FS'!F55-1,0) -> 0.13333333 | H13: =IFERROR('Historical & Forecasted FS'!H55/'Historical & Forecasted FS'!G55-1,0) -> 0.10294118 | I13: =IFERROR('Historical & Forecasted FS'!I55/'Historical & Forecasted FS'!H55-1,0) -> 0.066666667 | J13: =IFERROR('Historical & Forecasted FS'!J55/'Historical & Forecasted FS'!I55-1,0) -> 0.0625 | K13: =IFERROR('Historical & Forecasted FS'!K55/'Historical & Forecasted FS'!J55-1,0) -> 0.058823529 | L13: =IFERROR('Historical & Forecasted FS'!L55/'Historical & Forecasted FS'!K55-1,0) -> 0.044444444 | N13: =IFERROR(AVERAGE(D13:L13),0) -> 0.082952751 | O13: =IFERROR(MEDIAN(D13:L13),0) -> 0.086956522 | P13: =AVERAGE(H13:L13) -> 0.067075163
B15: ="Gross" & " " & "Margin" -> Gross Margin | C15: =IFERROR('Historical & Forecasted FS'!C15,0) -> 0.38588036 | D15: =IFERROR('Historical & Forecasted FS'!D15,0) -> 0.40059902 | E15: =IFERROR('Historical & Forecasted FS'!E15,0) -> 0.39075956 | F15: =IFERROR('Historical & Forecasted FS'!F15,0) -> 0.3846986 | G15: =IFERROR('Historical & Forecasted FS'!G15,0) -> 0.38343719 | H15: =IFERROR('Historical & Forecasted FS'!H15,0) -> 0.37817768 | I15: =IFERROR('Historical & Forecasted FS'!I15,0) -> 0.38233248 | J15: =IFERROR('Historical & Forecasted FS'!J15,0) -> 0.4177936 | ... L15: =IFERROR('Historical & Forecasted FS'!L15,0) -> 0.4413113 | N15: =IFERROR(AVERAGE(C15:L15),0) -> 0.39980861 | O15: =IFERROR(MEDIAN(C15:L15),0) -> 0.38831996 | P15: =AVERAGE(H15:L15) -> 0.41054227 | Q15: ='Data Sheet'!G303 -> 0.497595
B16: ="EBITDA" & " " & "Margin" -> EBITDA Margin | C16: =IFERROR('Historical & Forecasted FS'!C30,0) -> 0.32467518 | D16: =IFERROR('Historical & Forecasted FS'!D30,0) -> 0.34737608 | E16: =IFERROR('Historical & Forecasted FS'!E30,0) -> 0.32706978 | F16: =IFERROR('Historical & Forecasted FS'!F30,0) -> 0.31191272 | G16: =IFERROR('Historical & Forecasted FS'!G30,0) -> 0.30799149 | H16: =IFERROR('Historical & Forecasted FS'!H30,0) -> 0.29394559 | I16: =IFERROR('Historical & Forecasted FS'!I30,0) -> 0.28174781 | J16: =IFERROR('Historical & Forecasted FS'!J30,0) -> 0.3286698 | ... L16: =IFERROR('Historical & Forecasted FS'!L30,0) -> 0.32826748 | N16: =IFERROR(AVERAGE(C16:L16),0) -> 0.31827027 | O16: =IFERROR(MEDIAN(C16:L16),0) -> 0.32587248 | P16: =AVERAGE(H16:L16) -> 0.31273548 | Q16: ='Data Sheet'!G305 -> 0.3162248
B17: ="EBIT" & " " & "Margin" -> EBIT Margin | C17: =IFERROR('Historical & Forecasted FS'!C24,0) -> 0.28722339 | D17: =IFERROR('Historical & Forecasted FS'!D24,0) -> 0.30477291 | E17: =IFERROR('Historical & Forecasted FS'!E24,0) -> 0.2783541 | F17: =IFERROR('Historical & Forecasted FS'!F24,0) -> 0.26760428 | G17: =IFERROR('Historical & Forecasted FS'!G24,0) -> 0.26694027 | H17: =IFERROR('Historical & Forecasted FS'!H24,0) -> 0.24572017 | I17: =IFERROR('Historical & Forecasted FS'!I24,0) -> 0.24147314 | J17: =IFERROR('Historical & Forecasted FS'!J24,0) -> 0.29782378 | ... L17: =IFERROR('Historical & Forecasted FS'!L24,0) -> 0.29821412 | N17: =IFERROR(AVERAGE(C17:L17),0) -> 0.27910136 | O17: =IFERROR(MEDIAN(C17:L17),0) -> 0.28278875 | P17: =AVERAGE(H17:L17) -> 0.27722373 | Q17: ='Data Sheet'!G307 -> 0.250949
B18: ="EBT" & " " & "Margin" -> EBT Margin | C18: =IFERROR('Historical & Forecasted FS'!C42,0) -> 0.29258459 | D18: =IFERROR('Historical & Forecasted FS'!D42,0) -> 0.31027106 | E18: =IFERROR('Historical & Forecasted FS'!E42,0) -> 0.28460529 | F18: =IFERROR('Historical & Forecasted FS'!F42,0) -> 0.27957895 | G18: =IFERROR('Historical & Forecasted FS'!G42,0) -> 0.27448935 | H18: =IFERROR('Historical & Forecasted FS'!H42,0) -> 0.25266552 | I18: =IFERROR('Historical & Forecasted FS'!I42,0) -> 0.2443983 | J18: =IFERROR('Historical & Forecasted FS'!J42,0) -> 0.29852905 | ... L18: =IFERROR('Historical & Forecasted FS'!L42,0) -> 0.29674002 | N18: =IFERROR(AVERAGE(C18:L18),0) -> 0.28359026 | O18: =IFERROR(MEDIAN(C18:L18),0) -> 0.28859494 | P18: =AVERAGE(H18:L18) -> 0.27887467 | Q18: ='Data Sheet'!G380/'Data Sheet'!G373 -> 0.246139
B19: ="Net Profit" & " " & "Margin" -> Net Profit Margin | C19: =IFERROR('Historical & Forecasted FS'!C48,0) -> 0.21614377 | D19: =IFERROR('Historical & Forecasted FS'!D48,0) -> 0.22845774 | E19: =IFERROR('Historical & Forecasted FS'!E48,0) -> 0.21186798 | F19: =IFERROR('Historical & Forecasted FS'!F48,0) -> 0.21092421 | G19: =IFERROR('Historical & Forecasted FS'!G48,0) -> 0.22414202 | H19: =IFERROR('Historical & Forecasted FS'!H48,0) -> 0.21238095 | I19: =IFERROR('Historical & Forecasted FS'!I48,0) -> 0.20913611 | J19: =IFERROR('Historical & Forecasted FS'!J48,0) -> 0.25881793 | ... L19: =IFERROR('Historical & Forecasted FS'!L48,0) -> 0.25306234 | N19: =IFERROR(AVERAGE(C19:L19),0) -> 0.22780295 | O19: =IFERROR(MEDIAN(C19:L19),0) -> 0.22014289 | P19: =AVERAGE(H19:L19) -> 0.23729875 | Q19: ='Data Sheet'!G311 -> 0.2046742
B21: ="SalesExpenses" & " " & "%Sales" -> SalesExpenses %Sales | C21: =IFERROR('Historical & Forecasted FS'!C18,0) -> 0.065609016 | D21: =IFERROR('Historical & Forecasted FS'!D18,0) -> 0.061309715 | E21: =IFERROR('Historical & Forecasted FS'!E18,0) -> 0.065822973 | F21: =IFERROR('Historical & Forecasted FS'!F18,0) -> 0.066573894 | G21: =IFERROR('Historical & Forecasted FS'!G18,0) -> 0.062896515 | H21: =IFERROR('Historical & Forecasted FS'!H18,0) -> 0.070126146 | I21: =IFERROR('Historical & Forecasted FS'!I18,0) -> 0.07254977 | J21: =IFERROR('Historical & Forecasted FS'!J18,0) -> 0.060065552 | ... L21: =IFERROR('Historical & Forecasted FS'!L18,0) -> 0.065048202 | N21: =IFERROR(AVERAGE(C21:L21),0) -> 0.065363916 | O21: =IFERROR(MEDIAN(C21:L21),0) -> 0.065328609 | P21: =AVERAGE(H21:L21) -> 0.06628541 | Q21: ='Data Sheet'!G375/'Data Sheet'!G373 -> 0.14879071
B22: ="Depreciation" & " " & "%Sales" -> Depreciation %Sales | C22: =IFERROR('Historical & Forecasted FS'!C27,0) -> 0.03745179 | D22: =IFERROR('Historical & Forecasted FS'!D27,0) -> 0.042603171 | E22: =IFERROR('Historical & Forecasted FS'!E27,0) -> 0.048715678 | F22: =IFERROR('Historical & Forecasted FS'!F27,0) -> 0.044308436 | G22: =IFERROR('Historical & Forecasted FS'!G27,0) -> 0.041051225 | H22: =IFERROR('Historical & Forecasted FS'!H27,0) -> 0.048225418 | I22: =IFERROR('Historical & Forecasted FS'!I27,0) -> 0.040274666 | J22: =IFERROR('Historical & Forecasted FS'!J27,0) -> 0.030846024 | ... L22: =IFERROR('Historical & Forecasted FS'!L27,0) -> 0.030053355 | N22: =IFERROR(AVERAGE(C22:L22),0) -> 0.039168906 | O22: =IFERROR(MEDIAN(C22:L22),0) -> 0.040662945 | P22: =AVERAGE(H22:L22) -> 0.035511752
B24: Financial Health Ratios:
B25: Return on Capital Employed | C25: =IFERROR('Historical & Forecasted FS'!C23/('Historical & Forecasted FS'!C97+'Historical & Forecasted FS'!C106),0) -> 0.3117922 | D25: =IFERROR('Historical & Forecasted FS'!D23/('Historical & Forecasted FS'!D97+'Historical & Forecasted FS'!D106),0) -> 0.33961904 | E25: =IFERROR('Historical & Forecasted FS'!E23/('Historical & Forecasted FS'!E97+'Historical & Forecasted FS'!E106),0) -> 0.24733806 | F25: =IFERROR('Historical & Forecasted FS'!F23/('Historical & Forecasted FS'!F97+'Historical & Forecasted FS'!F106),0) -> 0.22347134 | G25: =IFERROR('Historical & Forecasted FS'!G23/('Historical & Forecasted FS'!G97+'Historical & Forecasted FS'!G106),0) -> 0.2838236 | H25: =IFERROR('Historical & Forecasted FS'!H23/('Historical & Forecasted FS'!H97+'Historical & Forecasted FS'!H106),0) -> 0.27461576 | I25: =IFERROR('Historical & Forecasted FS'!I23/('Historical & Forecasted FS'!I97+'Historical & Forecasted FS'!I106),0) -> 0.30338313 | J25: =IFERROR('Historical & Forecasted FS'!J23/('Historical & Forecasted FS'!J97+'Historical & Forecasted FS'!J106),0) -> 0.48309913 | ... L25: =IFERROR('Historical & Forecasted FS'!L23/('Historical & Forecasted FS'!L97+'Historical & Forecasted FS'!L106),0) -> 0.55144615 | N25: =IFERROR(AVERAGE(C25:L25),0) -> 0.36194598 | O25: =IFERROR(MEDIAN(C25:L25),0) -> 0.30758766 | P25: =AVERAGE(H25:L25) -> 0.4426831 | Q25: ='Data Sheet'!G298 -> 0.2399538
B26: Retained Earnings% | C26: =IFERROR('Historical & Forecasted FS'!C58,0) -> 0.72681002 | D26: =IFERROR('Historical & Forecasted FS'!D58,0) -> 0.79103446 | E26: =IFERROR('Historical & Forecasted FS'!E58,0) -> 0.74304364 | F26: =IFERROR('Historical & Forecasted FS'!F58,0) -> 0.74555061 | G26: =IFERROR('Historical & Forecasted FS'!G58,0) -> 0.7827424 | H26: =IFERROR('Historical & Forecasted FS'!H58,0) -> 0.75876451 | I26: =IFERROR('Historical & Forecasted FS'!I58,0) -> 0.7634354 | J26: =IFERROR('Historical & Forecasted FS'!J58,0) -> 0.85252674 | ... L26: =IFERROR('Historical & Forecasted FS'!L58,0) -> 0.84930092 | N26: =IFERROR(AVERAGE(C26:L26),0) -> 0.78694346 | O26: =IFERROR(MEDIAN(C26:L26),0) -> 0.7730889 | P26: =AVERAGE(H26:L26) -> 0.8160507 | Q26: =1-'Data Sheet'!G396 -> 0.6115788
B27: Return on Equity% | C27: =IFERROR('Historical & Forecasted FS'!C47/('Historical & Forecasted FS'!C106),0) -> 0.35420047 | D27: =IFERROR('Historical & Forecasted FS'!D47/('Historical & Forecasted FS'!D106),0) -> 0.44735453 | E27: =IFERROR('Historical & Forecasted FS'!E47/('Historical & Forecasted FS'!E106),0) -> 0.3562367 | F27: =IFERROR('Historical & Forecasted FS'!F47/('Historical & Forecasted FS'!F106),0) -> 0.36070184 | G27: =IFERROR('Historical & Forecasted FS'!G47/('Historical & Forecasted FS'!G106),0) -> 0.55560118 | H27: ='Historical & Forecasted FS'!H47/(('Historical & Forecasted FS'!H106+'Historical & Forecasted FS'!G106)/2) -> 0.55917221 | I27: =IFERROR('Historical & Forecasted FS'!I47/(('Historical & Forecasted FS'!I106+'Historical & Forecasted FS'!H106)/2),0) -> 0.73685562 | J27: =IFERROR('Historical & Forecasted FS'!J47/(('Historical & Forecasted FS'!J106+'Historical & Forecasted FS'!I106)/2),0) -> 1.4744333 | K27: =IFERROR('Historical & Forecasted FS'!K47/(('Historical & Forecasted FS'!K106+'Historical & Forecasted FS'!J106)/2),0) -> 1.7545929 | L27: =IFERROR('Historical & Forecasted FS'!L47/(('Historical & Forecasted FS'!L106+'Historical & Forecasted FS'!K106)/2),0) -> 1.7194951 | N27: =IFERROR(AVERAGE(C27:L27),0) -> 0.83186439 | O27: =IFERROR(MEDIAN(C27:L27),0) -> 0.5573867 | P27: =AVERAGE(H27:L27) -> 1.2489098 | Q27: ='Data Sheet'!G299 -> 0.3119468
B28: Self Sustained Growth Rate | C28: =IFERROR(C27*C26,0) -> 0.25743645 | D28: =IFERROR(D27*D26,0) -> 0.35387285 | E28: =IFERROR(E27*E26,0) -> 0.26469941 | F28: =IFERROR(F27*F26,0) -> 0.26892148 | G28: =IFERROR(G27*G26,0) -> 0.43489261 | H28: =IFERROR(H27*H26,0) -> 0.42428003 | I28: =IFERROR(I27*I26,0) -> 0.56254166 | J28: =IFERROR(J27*J26,0) -> 1.2569939 | ... L28: =IFERROR(L27*L26,0) -> 1.4603688 | N28: =IFERROR(AVERAGE(C28:L28),0) -> 0.67863351 | O28: =IFERROR(MEDIAN(C28:L28),0) -> 0.42958632 | P28: =AVERAGE(H28:L28) -> 1.0413025 | Q28: =Q27*Q26 -> 0.19078005
B29: Interest Coverage Ratio | C29: =IFERROR('Historical & Forecasted FS'!C23/-'Data Sheet'!B34,0) -> 136.72656 | D29: =IFERROR('Historical & Forecasted FS'!D23/-'Data Sheet'!C34,0) -> 97.175989 | E29: =IFERROR('Historical & Forecasted FS'!E23/-'Data Sheet'!D34,0) -> 41.225275 | F29: =IFERROR('Historical & Forecasted FS'!F23/-'Data Sheet'!E34,0) -> 26.407232 | G29: =IFERROR('Historical & Forecasted FS'!G23/-'Data Sheet'!F34,0) -> 21.882099 | H29: =IFERROR('Historical & Forecasted FS'!H23/-'Data Sheet'!G34,0) -> 17.877517 | I29: =IFERROR('Historical & Forecasted FS'!I23/-'Data Sheet'!H34,0) -> 23.072746 | J29: =IFERROR('Historical & Forecasted FS'!J23/-'Data Sheet'!I34,0) -> 41.190548 | ... L29: =IFERROR('Historical & Forecasted FS'!L23/-'Data Sheet'!K34,0) -> 29.062039 | N29: =IFERROR(AVERAGE(C29:L29),0) -> 47.536958 | O29: =IFERROR(MEDIAN(C29:L29),0) -> 34.905806 | P29: =AVERAGE(H29:L29) -> 30.390485 | Q29: ='Data Sheet'!G351 -> 18.186367
B30: Debt/Equity | H30: =SUM('Historical & Forecasted FS'!H92:H93,'Historical & Forecasted FS'!H85:H87)/'Historical & Forecasted FS'!H106 -> 1.1940478 | I30: =SUM('Historical & Forecasted FS'!I92:I93,'Historical & Forecasted FS'!I85:I87)/'Historical & Forecasted FS'!I106 -> 1.8714397 | J30: =SUM('Historical & Forecasted FS'!J92:J93,'Historical & Forecasted FS'!J85:J87)/'Historical & Forecasted FS'!J106 -> 2.1639246 | K30: =SUM('Historical & Forecasted FS'!K92:K93,'Historical & Forecasted FS'!K85:K87)/'Historical & Forecasted FS'!K106 -> 2.6144616 | L30: =SUM('Historical & Forecasted FS'!L92:L93,'Historical & Forecasted FS'!L85:L87)/'Historical & Forecasted FS'!L106 -> 1.994175 | P30: =AVERAGE(H30:L30) -> 1.9676097 | Q30: ='Data Sheet'!G446/'Data Sheet'!G441 -> 0.72229341
B32: Working Capital Ratios:
B33: ="Receivable" & " " & "Turnover" -> Receivable Turnover | D33: =IFERROR('Historical & Forecasted FS'!D8/(('Historical & Forecasted FS'!D67+'Historical & Forecasted FS'!C67)/2),0) -> 13.624122 | E33: =IFERROR('Historical & Forecasted FS'!E8/(('Historical & Forecasted FS'!E67+'Historical & Forecasted FS'!D67)/2),0) -> 13.228169 | F33: =IFERROR('Historical & Forecasted FS'!F8/(('Historical & Forecasted FS'!F67+'Historical & Forecasted FS'!E67)/2),0) -> 13.63352 | G33: =IFERROR('Historical & Forecasted FS'!G8/(('Historical & Forecasted FS'!G67+'Historical & Forecasted FS'!F67)/2),0) -> 12.936922 | H33: =IFERROR('Historical & Forecasted FS'!H8/(('Historical & Forecasted FS'!H67+'Historical & Forecasted FS'!G67)/2),0) -> 11.284438 | I33: =IFERROR('Historical & Forecasted FS'!I8/(('Historical & Forecasted FS'!I67+'Historical & Forecasted FS'!H67)/2),0) -> 14.061107 | J33: =IFERROR('Historical & Forecasted FS'!J8/(('Historical & Forecasted FS'!J67+'Historical & Forecasted FS'!I67)/2),0) -> 17.256333 | K33: =IFERROR('Historical & Forecasted FS'!K8/(('Historical & Forecasted FS'!K67+'Historical & Forecasted FS'!J67)/2),0) -> 14.480849 | L33: =IFERROR('Historical & Forecasted FS'!L8/(('Historical & Forecasted FS'!L67+'Historical & Forecasted FS'!K67)/2),0) -> 13.287284 | N33: =IFERROR(AVERAGE(C33:L33),0) -> 13.754749 | O33: =IFERROR(MEDIAN(C33:L33),0) -> 13.624122 | P33: =AVERAGE(H33:L33) -> 14.074002 | Q33: ='Data Sheet'!G320 -> 7.2436786
B34: ="Payable" & " " & "Turnover" -> Payable Turnover | D34: ='Historical & Forecasted FS'!D11/(('Historical & Forecasted FS'!D84+'Historical & Forecasted FS'!C84)/2) -> 4.2654142 | E34: ='Historical & Forecasted FS'!E11/(('Historical & Forecasted FS'!E84+'Historical & Forecasted FS'!D84)/2) -> 3.6100242 | F34: ='Historical & Forecasted FS'!F11/(('Historical & Forecasted FS'!F84+'Historical & Forecasted FS'!E84)/2) -> 3.4597724 | G34: ='Historical & Forecasted FS'!G11/(('Historical & Forecasted FS'!G84+'Historical & Forecasted FS'!F84)/2) -> 3.2708679 | H34: ='Historical & Forecasted FS'!H11/(('Historical & Forecasted FS'!H84+'Historical & Forecasted FS'!G84)/2) -> 3.1683444 | I34: ='Historical & Forecasted FS'!I11/(('Historical & Forecasted FS'!I84+'Historical & Forecasted FS'!H84)/2) -> 3.8304568 | J34: ='Historical & Forecasted FS'!J11/(('Historical & Forecasted FS'!J84+'Historical & Forecasted FS'!I84)/2) -> 4.3886914 | K34: ='Historical & Forecasted FS'!K11/(('Historical & Forecasted FS'!K84+'Historical & Forecasted FS'!J84)/2) -> 3.7609314 | L34: ='Historical & Forecasted FS'!L11/(('Historical & Forecasted FS'!L84+'Historical & Forecasted FS'!K84)/2) -> 3.3795275 | N34: =IFERROR(AVERAGE(C34:L34),0) -> 3.6815589 | O34: =IFERROR(MEDIAN(C34:L34),0) -> 3.6100242 | P34: =AVERAGE(H34:L34) -> 3.7055903 | Q34: ='Data Sheet'!G374/'Data Sheet'!G428 -> 4.8710565
B35: ="Inventory" & " " & "Turnover" -> Inventory Turnover | D35: =IFERROR('Historical & Forecasted FS'!D11/(('Historical & Forecasted FS'!D70+'Historical & Forecasted FS'!C70)/2),0) -> 62.820179 | E35: =IFERROR('Historical & Forecasted FS'!E11/(('Historical & Forecasted FS'!E70+'Historical & Forecasted FS'!D70)/2),0) -> 58.636911 | F35: =IFERROR('Historical & Forecasted FS'!F11/(('Historical & Forecasted FS'!F70+'Historical & Forecasted FS'!E70)/2),0) -> 40.37441 | G35: =IFERROR('Historical & Forecasted FS'!G11/(('Historical & Forecasted FS'!G70+'Historical & Forecasted FS'!F70)/2),0) -> 37.170809 | H35: =IFERROR('Historical & Forecasted FS'!H11/(('Historical & Forecasted FS'!H70+'Historical & Forecasted FS'!G70)/2),0) -> 40.134458 | I35: =IFERROR('Historical & Forecasted FS'!I11/(('Historical & Forecasted FS'!I70+'Historical & Forecasted FS'!H70)/2),0) -> 41.522958 | J35: =IFERROR('Historical & Forecasted FS'!J11/(('Historical & Forecasted FS'!J70+'Historical & Forecasted FS'!I70)/2),0) -> 40.03026 | K35: =IFERROR('Historical & Forecasted FS'!K11/(('Historical & Forecasted FS'!K70+'Historical & Forecasted FS'!J70)/2),0) -> 38.789866 | L35: =IFERROR('Historical & Forecasted FS'!L11/(('Historical & Forecasted FS'!L70+'Historical & Forecasted FS'!K70)/2),0) -> 37.977654 | N35: =IFERROR(AVERAGE(C35:L35),0) -> 44.161945 | O35: =IFERROR(MEDIAN(C35:L35),0) -> 40.134458 | P35: =AVERAGE(H35:L35) -> 39.691039 | Q35: ='Data Sheet'!G321 -> 8.9695414
B36: ="Fixed Asset" & " " & "Turnover" -> Fixed Asset Turnover | C36: =IFERROR('Historical & Forecasted FS'!C8/'Historical & Forecasted FS'!C76,0) -> 8.8632176 | D36: =IFERROR('Historical & Forecasted FS'!D8/'Historical & Forecasted FS'!D76,0) -> 10.400739 | E36: =IFERROR('Historical & Forecasted FS'!E8/'Historical & Forecasted FS'!E76,0) -> 7.9836727 | F36: =IFERROR('Historical & Forecasted FS'!F8/'Historical & Forecasted FS'!F76,0) -> 6.7854838 | G36: =IFERROR('Historical & Forecasted FS'!G8/'Historical & Forecasted FS'!G76,0) -> 6.4302489 | H36: =IFERROR('Historical & Forecasted FS'!H8/'Historical & Forecasted FS'!H76,0) -> 6.9606185 | I36: =IFERROR('Historical & Forecasted FS'!I8/'Historical & Forecasted FS'!I76,0) -> 6.0551218 | J36: =IFERROR('Historical & Forecasted FS'!J8/AVERAGE('Historical & Forecasted FS'!J76,'Historical & Forecasted FS'!I76),0) -> 7.7125328 | K36: =IFERROR('Historical & Forecasted FS'!K8/AVERAGE('Historical & Forecasted FS'!K76,'Historical & Forecasted FS'!J76),0) -> 7.7273003 | L36: =IFERROR('Historical & Forecasted FS'!L8/AVERAGE('Historical & Forecasted FS'!L76,'Historical & Forecasted FS'!K76),0) -> 7.1702366 | N36: =IFERROR(AVERAGE(C36:L36),0) -> 7.6089172 | O36: =IFERROR(MEDIAN(C36:L36),0) -> 7.4413847 | P36: =AVERAGE(H36:L36) -> 7.125162 | Q36: ='Data Sheet'!G319 -> 4.2199338
B37: ="Capital" & " " & "Turnover" -> Capital Turnover | C37: =IFERROR('Historical & Forecasted FS'!C8/'Historical & Forecasted FS'!C106,0) -> 1.6387263 | D37: =IFERROR('Historical & Forecasted FS'!D8/AVERAGE('Historical & Forecasted FS'!D106,'Historical & Forecasted FS'!C106),0) -> 2.0243653 | E37: =IFERROR('Historical & Forecasted FS'!E8/AVERAGE('Historical & Forecasted FS'!E106,'Historical & Forecasted FS'!D106),0) -> 1.7418055 | F37: =IFERROR('Historical & Forecasted FS'!F8/AVERAGE('Historical & Forecasted FS'!F106,'Historical & Forecasted FS'!E106),0) -> 1.7479031 | G37: =IFERROR('Historical & Forecasted FS'!G8/AVERAGE('Historical & Forecasted FS'!G106,'Historical & Forecasted FS'!F106),0) -> 2.202335 | H37: =IFERROR('Historical & Forecasted FS'!H8/AVERAGE('Historical & Forecasted FS'!H106,'Historical & Forecasted FS'!G106),0) -> 2.6328737 | I37: =IFERROR('Historical & Forecasted FS'!I8/AVERAGE('Historical & Forecasted FS'!I106,'Historical & Forecasted FS'!H106),0) -> 3.5233304 | J37: =IFERROR('Historical & Forecasted FS'!J8/AVERAGE('Historical & Forecasted FS'!J106,'Historical & Forecasted FS'!I106),0) -> 5.6967975 | K37: =IFERROR('Historical & Forecasted FS'!K8/AVERAGE('Historical & Forecasted FS'!K106,'Historical & Forecasted FS'!J106),0) -> 6.9325082 | L37: =IFERROR('Historical & Forecasted FS'!L8/AVERAGE('Historical & Forecasted FS'!L106,'Historical & Forecasted FS'!K106),0) -> 6.7947491 | N37: =IFERROR(AVERAGE(C37:L37),0) -> 3.4935394 | O37: =IFERROR(MEDIAN(C37:L37),0) -> 2.4176044 | P37: =AVERAGE(H37:L37) -> 5.1160518 | Q37: ='Data Sheet'!G373/'Data Sheet'!G441 -> 1.4413536
B39: (In days)
B40: ="Receivable" & " " & "Days" -> Receivable Days | D40: =IFERROR(365/D33,0) -> 26.790717 | E40: =IFERROR(365/E33,0) -> 27.592632 | F40: =IFERROR(365/F33,0) -> 26.77225 | G40: =IFERROR(365/G33,0) -> 28.213822 | H40: =IFERROR(365/H33,0) -> 32.34543 | I40: =IFERROR(365/I33,0) -> 25.958126 | J40: =IFERROR(365/J33,0) -> 21.151655 | K40: =IFERROR(365/K33,0) -> 25.205704 | L40: =IFERROR(365/L33,0) -> 27.469872 | N40: =IFERROR(AVERAGE(C40:L40),0) -> 26.833357 | O40: =IFERROR(MEDIAN(C40:L40),0) -> 26.790717 | P40: =AVERAGE(H40:L40) -> 26.426158 | Q40: ='Data Sheet'!G338 -> 50.406202
B41: ="Payable" & " " & "Days" -> Payable Days | D41: =IFERROR(365/D34,0) -> 85.571994 | E41: =IFERROR(365/E34,0) -> 101.10736 | F41: =IFERROR(365/F34,0) -> 105.49827 | G41: =IFERROR(365/G34,0) -> 111.59118 | H41: =IFERROR(365/H34,0) -> 115.20212 | I41: =IFERROR(365/I34,0) -> 95.288896 | J41: =IFERROR(365/J34,0) -> 83.168299 | K41: =IFERROR(365/K34,0) -> 97.050428 | L41: =IFERROR(365/L34,0) -> 108.00326 | N41: =IFERROR(AVERAGE(C41:L41),0) -> 100.27576 | O41: =IFERROR(MEDIAN(C41:L41),0) -> 101.10736 | P41: =AVERAGE(H41:L41) -> 99.742602 | Q41: ='Data Sheet'!G340 -> 71.658703
B42: ="Inventory" & " " & "Days" -> Inventory Days | D42: =IFERROR(365/D35,0) -> 5.8102349 | E42: =IFERROR(365/E35,0) -> 6.2247481 | F42: =IFERROR(365/F35,0) -> 9.0403799 | G42: =IFERROR(365/G35,0) -> 9.8195333 | H42: =IFERROR(365/H35,0) -> 9.0944295 | I42: =IFERROR(365/I35,0) -> 8.7903178 | J42: =IFERROR(365/J35,0) -> 9.1181021 | K42: =IFERROR(365/K35,0) -> 9.4096741 | L42: =IFERROR(365/L35,0) -> 9.610915 | N42: =IFERROR(AVERAGE(C42:L42),0) -> 8.5464816 | O42: =IFERROR(MEDIAN(C42:L42),0) -> 9.0944295 | P42: =AVERAGE(H42:L42) -> 9.2046877 | Q42: ='Data Sheet'!G339 -> 42.19878
B43: ="Cash Conversion Cycle" -> Cash Conversion Cycle | D43: =IFERROR(SUM(D40,D42)-D41,0) -> -52.971041 | E43: =IFERROR(SUM(E40,E42)-E41,0) -> -67.289976 | F43: =IFERROR(SUM(F40,F42)-F41,0) -> -69.68564 | G43: =IFERROR(SUM(G40,G42)-G41,0) -> -73.557823 | H43: =IFERROR(SUM(H40,H42)-H41,0) -> -73.762264 | I43: =IFERROR(SUM(I40,I42)-I41,0) -> -60.540453 | J43: =IFERROR(SUM(J40,J42)-J41,0) -> -52.898542 | K43: =IFERROR(SUM(K40,K42)-K41,0) -> -62.43505 | L43: =IFERROR(SUM(L40,L42)-L41,0) -> -70.922477 | N43: =IFERROR(AVERAGE(C43:L43),0) -> -64.895918 | O43: =IFERROR(MEDIAN(C43:L43),0) -> -67.289976 | P43: =AVERAGE(H43:L43) -> -64.111757 | Q43: ='Data Sheet'!G341 -> 20.94628
B45: Cashflow Ratios:
B46: CFO/Sales | C46: =IFERROR('Historical & Forecasted FS'!C126/'Historical & Forecasted FS'!C8,0) -> 0.32666648 | D46: =IFERROR('Historical & Forecasted FS'!D126/'Historical & Forecasted FS'!D8,0) -> 0.3477141 | E46: =IFERROR('Historical & Forecasted FS'!E126/'Historical & Forecasted FS'!E8,0) -> 0.30713832 | F46: =IFERROR('Historical & Forecasted FS'!F126/'Historical & Forecasted FS'!F8,0) -> 0.28017223 | G46: =IFERROR('Historical & Forecasted FS'!G126/'Historical & Forecasted FS'!G8,0) -> 0.29154916 | H46: =IFERROR('Historical & Forecasted FS'!H126/'Historical & Forecasted FS'!H8,0) -> 0.26670997 | I46: =IFERROR('Historical & Forecasted FS'!I126/'Historical & Forecasted FS'!I8,0) -> 0.29387829 | J46: =IFERROR('Historical & Forecasted FS'!J126/'Historical & Forecasted FS'!J8,0) -> 0.28439903 | ... L46: =IFERROR('Historical & Forecasted FS'!L126/'Historical & Forecasted FS'!L8,0) -> 0.28840941 | N46: =IFERROR(AVERAGE(C46:L46),0) -> 0.2996407 | O46: =IFERROR(MEDIAN(C46:L46),0) -> 0.29271373 | P46: =AVERAGE(H46:L46) -> 0.28863335 | Q46: ='Data Sheet'!G461/'Data Sheet'!G373 -> 0.28668329
B47: CFO/Total Assets | C47: =IFERROR('Historical & Forecasted FS'!C126/'Historical & Forecasted FS'!C82,0) -> 0.25756236 | D47: =IFERROR('Historical & Forecasted FS'!D126/'Historical & Forecasted FS'!D82,0) -> 0.27989461 | E47: =IFERROR('Historical & Forecasted FS'!E126/'Historical & Forecasted FS'!E82,0) -> 0.20588711 | F47: =IFERROR('Historical & Forecasted FS'!F126/'Historical & Forecasted FS'!F82,0) -> 0.1711211 | G47: =IFERROR('Historical & Forecasted FS'!G126/'Historical & Forecasted FS'!G82,0) -> 0.21172739 | H47: =IFERROR('Historical & Forecasted FS'!H126/'Historical & Forecasted FS'!H82,0) -> 0.20498588 | I47: =IFERROR('Historical & Forecasted FS'!I126/'Historical & Forecasted FS'!I82,0) -> 0.24907993 | J47: =IFERROR('Historical & Forecasted FS'!J126/'Historical & Forecasted FS'!J82,0) -> 0.29640287 | ... L47: =IFERROR('Historical & Forecasted FS'!L126/'Historical & Forecasted FS'!L82,0) -> 0.31352334 | N47: =IFERROR(AVERAGE(C47:L47),0) -> 0.25364617 | O47: =IFERROR(MEDIAN(C47:L47),0) -> 0.25332114 | P47: =AVERAGE(H47:L47) -> 0.28205384 | Q47: ='Data Sheet'!G461/'Data Sheet'!G425 -> 0.16086545
B48: CFO/Total Debt | C48: =IFERROR('Historical & Forecasted FS'!C126/'Historical & Forecasted FS'!C97,0) -> 1.0504715 | D48: =IFERROR('Historical & Forecasted FS'!D126/'Historical & Forecasted FS'!D97,0) -> 0.89915911 | E48: =IFERROR('Historical & Forecasted FS'!E126/'Historical & Forecasted FS'!E97,0) -> 0.57878547 | F48: =IFERROR('Historical & Forecasted FS'!F126/'Historical & Forecasted FS'!F97,0) -> 0.45725413 | G48: =IFERROR('Historical & Forecasted FS'!G126/'Historical & Forecasted FS'!G97,0) -> 0.5428289 | H48: =IFERROR('Historical & Forecasted FS'!H126/'Historical & Forecasted FS'!H97,0) -> 0.48760453 | I48: =IFERROR('Historical & Forecasted FS'!I126/'Historical & Forecasted FS'!I97,0) -> 0.52674053 | J48: =IFERROR('Historical & Forecasted FS'!J126/'Historical & Forecasted FS'!J97,0) -> 0.64050581 | ... L48: =IFERROR('Historical & Forecasted FS'!L126/'Historical & Forecasted FS'!L97,0) -> 0.76168788 | N48: =IFERROR(AVERAGE(C48:L48),0) -> 0.67698196 | O48: =IFERROR(MEDIAN(C48:L48),0) -> 0.60964564 | P48: =AVERAGE(H48:L48) -> 0.6482641 | Q48: ='Data Sheet'!G461/'Data Sheet'!G446 -> 0.57208328

Sheet Common Size Statements
B6: ="Common Size Income Statement -"& " " &'Data Sheet'!$A$4 -> Common Size Income Statement - Apple Inc.
B8: Particulars | C8: ='Historical & Forecasted FS'!C6 -> 2014 | D8: ='Historical & Forecasted FS'!D6 -> 2015 | E8: ='Historical & Forecasted FS'!E6 -> 2016 | F8: ='Historical & Forecasted FS'!F6 -> 2017 | G8: ='Historical & Forecasted FS'!G6 -> 2018 | H8: ='Historical & Forecasted FS'!H6 -> 2019 | I8: ='Historical & Forecasted FS'!I6 -> 2020 | J8: ='Historical & Forecasted FS'!J6 -> 2021 | ... L8: ='Historical & Forecasted FS'!L6 -> 2023
B9: ='Historical & Forecasted FS'!B8 -> Sales | C9: ='Historical & Forecasted FS'!C8/'Historical & Forecasted FS'!C$8 -> 1 | D9: ='Historical & Forecasted FS'!D8/'Historical & Forecasted FS'!D$8 -> 1 | E9: ='Historical & Forecasted FS'!E8/'Historical & Forecasted FS'!E$8 -> 1 | F9: ='Historical & Forecasted FS'!F8/'Historical & Forecasted FS'!F$8 -> 1 | G9: ='Historical & Forecasted FS'!G8/'Historical & Forecasted FS'!G$8 -> 1 | H9: ='Historical & Forecasted FS'!H8/'Historical & Forecasted FS'!H$8 -> 1 | I9: ='Historical & Forecasted FS'!I8/'Historical & Forecasted FS'!I$8 -> 1 | J9: ='Historical & Forecasted FS'!J8/'Historical & Forecasted FS'!J$8 -> 1 | ... L9: ='Historical & Forecasted FS'!L8/'Historical & Forecasted FS'!L$8 -> 1
B10: ='Historical & Forecasted FS'!B11 -> COGS | C10: ='Historical & Forecasted FS'!C11/'Historical & Forecasted FS'!C$8 -> 0.61411964 | D10: ='Historical & Forecasted FS'!D11/'Historical & Forecasted FS'!D$8 -> 0.59940098 | E10: ='Historical & Forecasted FS'!E11/'Historical & Forecasted FS'!E$8 -> 0.60924044 | F10: ='Historical & Forecasted FS'!F11/'Historical & Forecasted FS'!F$8 -> 0.6153014 | G10: ='Historical & Forecasted FS'!G11/'Historical & Forecasted FS'!G$8 -> 0.61656281 | H10: ='Historical & Forecasted FS'!H11/'Historical & Forecasted FS'!H$8 -> 0.62182232 | I10: ='Historical & Forecasted FS'!I11/'Historical & Forecasted FS'!I$8 -> 0.61766752 | J10: ='Historical & Forecasted FS'!J11/'Historical & Forecasted FS'!J$8 -> 0.5822064 | ... L10: ='Historical & Forecasted FS'!L11/'Historical & Forecasted FS'!L$8 -> 0.5586887
B11: ='Historical & Forecasted FS'!B14 -> Gross Profit | C11: ='Historical & Forecasted FS'!C14/'Historical & Forecasted FS'!C$8 -> 0.38588036 | D11: ='Historical & Forecasted FS'!D14/'Historical & Forecasted FS'!D$8 -> 0.40059902 | E11: ='Historical & Forecasted FS'!E14/'Historical & Forecasted FS'!E$8 -> 0.39075956 | F11: ='Historical & Forecasted FS'!F14/'Historical & Forecasted FS'!F$8 -> 0.3846986 | G11: ='Historical & Forecasted FS'!G14/'Historical & Forecasted FS'!G$8 -> 0.38343719 | H11: ='Historical & Forecasted FS'!H14/'Historical & Forecasted FS'!H$8 -> 0.37817768 | I11: ='Historical & Forecasted FS'!I14/'Historical & Forecasted FS'!I$8 -> 0.38233248 | J11: ='Historical & Forecasted FS'!J14/'Historical & Forecasted FS'!J$8 -> 0.4177936 | ... L11: ='Historical & Forecasted FS'!L14/'Historical & Forecasted FS'!L$8 -> 0.4413113
B12: ='Historical & Forecasted FS'!B17 -> SG&A Expenses | C12: ='Historical & Forecasted FS'!C17/'Historical & Forecasted FS'!C$8 -> 0.065609016 | D12: ='Historical & Forecasted FS'!D17/'Historical & Forecasted FS'!D$8 -> 0.061309715 | E12: ='Historical & Forecasted FS'!E17/'Historical & Forecasted FS'!E$8 -> 0.065822973 | F12: ='Historical & Forecasted FS'!F17/'Historical & Forecasted FS'!F$8 -> 0.066573894 | G12: ='Historical & Forecasted FS'!G17/'Historical & Forecasted FS'!G$8 -> 0.062896515 | H12: ='Historical & Forecasted FS'!H17/'Historical & Forecasted FS'!H$8 -> 0.070126146 | I12: ='Historical & Forecasted FS'!I17/'Historical & Forecasted FS'!I$8 -> 0.07254977 | J12: ='Historical & Forecasted FS'!J17/'Historical & Forecasted FS'!J$8 -> 0.060065552 | ... L12: ='Historical & Forecasted FS'!L17/'Historical & Forecasted FS'!L$8 -> 0.065048202
